<?xml version="1.0"?>
<robot name="openarm_sim">
  
  <!-- Base link -->
  <link name="base_link">
    <visual>
      <geometry>
        <cylinder length="0.1" radius="0.05"/>
      </geometry>
      <material name="gray">
        <color rgba="0.5 0.5 0.5 1.0"/>
      </material>
    </visual>
  </link>

  <!-- Joint 1: Base rotation -->
  <joint name="joint1" type="revolute">
    <parent link="base_link"/>
    <child link="link1"/>
    <origin xyz="0 0 0.05" rpy="0 0 0"/>
    <axis xyz="0 0 1"/>
    <limit lower="-3.14" upper="3.14" effort="100" velocity="1.0"/>
  </joint>

  <link name="link1">
    <visual>
      <geometry>
        <cylinder length="0.2" radius="0.03"/>
      </geometry>
      <origin xyz="0 0 0.1" rpy="0 0 0"/>
      <material name="blue">
        <color rgba="0.2 0.4 0.8 1.0"/>
      </material>
    </visual>
  </link>

  <!-- Joint 2: Shoulder -->
  <joint name="joint2" type="revolute">
    <parent link="link1"/>
    <child link="link2"/>
    <origin xyz="0 0 0.2" rpy="0 0 0"/>
    <axis xyz="0 1 0"/>
    <limit lower="-3.14" upper="3.14" effort="100" velocity="1.0"/>
  </joint>

  <link name="link2">
    <visual>
      <geometry>
        <box size="0.05 0.05 0.25"/>
      </geometry>
      <origin xyz="0 0 0.125" rpy="0 0 0"/>
      <material name="green">
        <color rgba="0.2 0.8 0.4 1.0"/>
      </material>
    </visual>
  </link>

  <!-- Joint 3: Elbow -->
  <joint name="joint3" type="revolute">
    <parent link="link2"/>
    <child link="link3"/>
    <origin xyz="0 0 0.25" rpy="0 0 0"/>
    <axis xyz="0 1 0"/>
    <limit lower="-3.14" upper="3.14" effort="100" velocity="1.0"/>
  </joint>

  <link name="link3">
    <visual>
      <geometry>
        <box size="0.04 0.04 0.15"/>
      </geometry>
      <origin xyz="0 0 0.075" rpy="0 0 0"/>
      <material name="yellow">
        <color rgba="0.9 0.9 0.2 1.0"/>
      </material>
    </visual>
  </link>

  <!-- Joint 4: Wrist roll -->
  <joint name="joint4" type="revolute">
    <parent link="link3"/>
    <child link="link4"/>
    <origin xyz="0 0 0.15" rpy="0 0 0"/>
    <axis xyz="0 0 1"/>
    <limit lower="-3.14" upper="3.14" effort="100" velocity="1.0"/>
  </joint>

  <link name="link4">
    <visual>
      <geometry>
        <cylinder length="0.1" radius="0.025"/>
      </geometry>
      <origin xyz="0 0 0.05" rpy="0 0 0"/>
      <material name="orange">
        <color rgba="0.9 0.5 0.2 1.0"/>
      </material>
    </visual>
  </link>

  <!-- Joint 5: Wrist pitch -->
  <joint name="joint5" type="revolute">
    <parent link="link4"/>
    <child link="link5"/>
    <origin xyz="0 0 0.1" rpy="0 0 0"/>
    <axis xyz="0 1 0"/>
    <limit lower="-3.14" upper="3.14" effort="100" velocity="1.0"/>
  </joint>

  <link name="link5">
    <visual>
      <geometry>
        <cylinder length="0.08" radius="0.02"/>
      </geometry>
      <origin xyz="0 0 0.04" rpy="0 0 0"/>
      <material name="red">
        <color rgba="0.9 0.2 0.2 1.0"/>
      </material>
    </visual>
  </link>

  <!-- Joint 6: Wrist yaw -->
  <joint name="joint6" type="revolute">
    <parent link="link5"/>
    <child link="link6"/>
    <origin xyz="0 0 0.08" rpy="0 0 0"/>
    <axis xyz="0 0 1"/>
    <limit lower="-3.14" upper="3.14" effort="100" velocity="1.0"/>
  </joint>

  <link name="link6">
    <visual>
      <geometry>
        <cylinder length="0.06" radius="0.015"/>
      </geometry>
      <origin xyz="0 0 0.03" rpy="0 0 0"/>
      <material name="purple">
        <color rgba="0.6 0.2 0.8 1.0"/>
      </material>
    </visual>
  </link>

  <!-- Joint 7: Gripper (fixed) -->
  <joint name="joint7" type="fixed">
    <parent link="link6"/>
    <child link="gripper_link"/>
    <origin xyz="0 0 0.06" rpy="0 0 0"/>
  </joint>

  <link name="gripper_link">
    <visual>
      <geometry>
        <box size="0.04 0.04 0.04"/>
      </geometry>
      <material name="white">
        <color rgba="0.9 0.9 0.9 1.0"/>
      </material>
    </visual>
  </link>

  <!-- End effector frame -->
  <joint name="ee_fixed_joint" type="fixed">
    <parent link="gripper_link"/>
    <child link="end_effector"/>
    <origin xyz="0 0 0.04" rpy="0 0 0"/>
  </joint>

  <link name="end_effector"/>

</robot>
